Workbook

Sheet INDICADORES
F2: GERENCIADOR FINANCEIRO | Q2: Código
Q3: R.PD.023
Q4: Revisão
Q5: 2.0
Q6: Data
Q7: 45513
Q8: Página
Q9: INDICADORES / R.PD.023
B11: FLUXO DE CAIXA | N11: EMPRESA | S11: ANO
N12: Cliente | S12: 2025
C14: SALDO | D14: RESULTADO
F15: JAN | G15: FEV | H15: MAR | I15: ABR | J15: MAI | K15: JUN | L15: JUL | M15: AGO | N15: SET | O15: OUT | P15: NOV | Q15: DEZ | S15: TOTAL
D16: LUCRO ESTIMADO | F16: =F38-F71 -> 0 | G16: =G38-G71 -> 0 | H16: =H38-H71 -> 0 | I16: =I38-I71 -> 0 | J16: =J38-J71 -> 0 | K16: =K38-K71 -> 0 | L16: =L38-L71 -> 0 | M16: =M38-M71 -> 0 | ... Q16: =Q38-Q71 -> 0 | S16: =SUM(F16:Q16) -> 0
D17: LUCRO OBTIDO | F17: =F39-F72 -> 0 | G17: =G39-G72 -> 0 | H17: =H39-H72 -> 0 | I17: =I39-I72 -> 0 | J17: =J39-J72 -> 0 | K17: =K39-K72 -> 0 | L17: =L39-L72 -> 0 | M17: =M39-M72 -> 0 | ... Q17: =Q39-Q72 -> 0 | S17: =SUM(F17:Q17) -> 0
D18: % LUCRATIVIDADE | F18: =IFERROR(F17/F39,"-") -> - | G18: =IFERROR(G17/G39,"-") -> - | H18: =IFERROR(H17/H39,"-") -> - | I18: =IFERROR(I17/I39,"-") -> - | J18: =IFERROR(J17/J39,"-") -> - | K18: =IFERROR(K17/K39,"-") -> - | L18: =IFERROR(L17/L39,"-") -> - | M18: =IFERROR(M17/M39,"-") -> - | ... Q18: =IFERROR(Q17/Q39,"-") -> - | S18: =IFERROR(AVERAGE(F18:Q18),"-") -> -
F19: =F17-F16 -> 0 | G19: =G17-G16 -> 0 | H19: =H17-H16 -> 0 | I19: =I17-I16 -> 0 | J19: =J17-J16 -> 0 | K19: =K17-K16 -> 0 | L19: =L17-L16 -> 0 | M19: =M17-M16 -> 0 | ... Q19: =Q17-Q16 -> 0 | S19: =S17-S16 -> 0
C36: ENTRADAS | D36: RECEITAS
F37: JAN | G37: FEV | H37: MAR | I37: ABR | J37: MAI | K37: JUN | L37: JUL | M37: AGO | N37: SET | O37: OUT | P37: NOV | Q37: DEZ | S37: TOTAL
D38: PREVISTO | F38: =RECEITAS!D16 -> 0 | G38: =RECEITAS!F16 -> 0 | H38: =RECEITAS!H16 -> 0 | I38: =RECEITAS!J16 -> 0 | J38: =RECEITAS!L16 -> 0 | K38: =RECEITAS!N16 -> 0 | L38: =RECEITAS!P16 -> 0 | M38: =RECEITAS!R16 -> 0 | N38: =RECEITAS!T16 -> 0 | O38: =RECEITAS!V16 -> 0 | P38: =RECEITAS!X16 -> 0 | Q38: =RECEITAS!Z16 -> 0 | S38: =SUM(F38:Q38) -> 0
D39: REALIZADO | F39: =RECEITAS!E16 -> 0 | G39: =RECEITAS!G16 -> 0 | H39: =RECEITAS!I16 -> 0 | I39: =RECEITAS!K16 -> 0 | J39: =RECEITAS!M16 -> 0 | K39: =RECEITAS!O16 -> 0 | L39: =RECEITAS!Q16 -> 0 | M39: =RECEITAS!S16 -> 0 | N39: =RECEITAS!U16 -> 0 | O39: =RECEITAS!W16 -> 0 | P39: =RECEITAS!Y16 -> 0 | Q39: =RECEITAS!AA16 -> 0 | S39: =SUM(F39:Q39) -> 0
G57: JAN | H57: FEV | I57: MAR | J57: ABR | K57: MAI | L57: JUN | M57: JUL | N57: AGO | O57: SET | P57: OUT | Q57: NOV | R57: DEZ
F58: =RECEITAS!C18 -> PRODUTOS/SERVIÇOS | G58: =RECEITAS!E22 -> 0 | H58: =RECEITAS!G22 -> 0 | I58: =RECEITAS!I22 -> 0 | J58: =RECEITAS!K22 -> 0 | K58: =RECEITAS!M22 -> 0 | L58: =RECEITAS!O22 -> 0 | M58: =RECEITAS!Q22 -> 0 | N58: =RECEITAS!S22 -> 0 | O58: =RECEITAS!U22 -> 0 | P58: =RECEITAS!W22 -> 0 | Q58: =RECEITAS!Y22 -> 0 | R58: =RECEITAS!AA22 -> 0
F59: =RECEITAS!C51 -> OUTRAS RECEITAS | G59: =RECEITAS!E55 -> 0 | H59: =RECEITAS!G55 -> 0 | I59: =RECEITAS!I55 -> 0 | J59: =RECEITAS!K55 -> 0 | K59: =RECEITAS!M55 -> 0 | L59: =RECEITAS!O55 -> 0 | M59: =RECEITAS!Q55 -> 0 | N59: =RECEITAS!S55 -> 0 | O59: =RECEITAS!U55 -> 0 | P59: =RECEITAS!W55 -> 0 | Q59: =RECEITAS!Y55 -> 0 | R59: =RECEITAS!AA55 -> 0
F60: =RECEITAS!C71 -> RECEITAS FINANCEIRAS | G60: =RECEITAS!E75 -> 0 | H60: =RECEITAS!G75 -> 0 | I60: =RECEITAS!I75 -> 0 | J60: =RECEITAS!K75 -> 0 | K60: =RECEITAS!M75 -> 0 | L60: =RECEITAS!O75 -> 0 | M60: =RECEITAS!Q75 -> 0 | N60: =RECEITAS!S75 -> 0 | O60: =RECEITAS!U75 -> 0 | P60: =RECEITAS!W75 -> 0 | Q60: =RECEITAS!Y75 -> 0 | R60: =RECEITAS!AA75 -> 0
F64: =G57 -> JAN | G64: =H57 -> FEV | H64: =I57 -> MAR | I64: =J57 -> ABR | J64: =K57 -> MAI | K64: =L57 -> JUN | L64: =M57 -> JUL | M64: =N57 -> AGO | ... Q64: =R57 -> DEZ | S64: TOTAL
D65: =F58 -> PRODUTOS/SERVIÇOS | F65: =G58 -> 0 | G65: =H58 -> 0 | H65: =I58 -> 0 | I65: =J58 -> 0 | J65: =K58 -> 0 | K65: =L58 -> 0 | L65: =M58 -> 0 | M65: =N58 -> 0 | ... Q65: =R58 -> 0 | S65: =SUM(F65:Q65) -> 0
D66: =F59 -> OUTRAS RECEITAS | F66: =G59 -> 0 | G66: =H59 -> 0 | H66: =I59 -> 0 | I66: =J59 -> 0 | J66: =K59 -> 0 | K66: =L59 -> 0 | L66: =M59 -> 0 | M66: =N59 -> 0 | ... Q66: =R59 -> 0 | S66: =SUM(F66:Q66) -> 0
D67: =F60 -> RECEITAS FINANCEIRAS | F67: =G60 -> 0 | G67: =H60 -> 0 | H67: =I60 -> 0 | I67: =J60 -> 0 | J67: =K60 -> 0 | K67: =L60 -> 0 | L67: =M60 -> 0 | M67: =N60 -> 0 | ... Q67: =R60 -> 0 | S67: =SUM(F67:Q67) -> 0
C69: SAÍDAS | D69: GASTOS
F70: JAN | G70: FEV | H70: MAR | I70: ABR | J70: MAI | K70: JUN | L70: JUL | M70: AGO | N70: SET | O70: OUT | P70: NOV | Q70: DEZ | S70: TOTAL
D71: PREVISTO | F71: =GASTOS!E16 -> 0 | G71: =GASTOS!G16 -> 0 | H71: =GASTOS!I16 -> 0 | I71: =GASTOS!K16 -> 0 | J71: =GASTOS!M16 -> 0 | K71: =GASTOS!O16 -> 0 | L71: =GASTOS!Q16 -> 0 | M71: =GASTOS!S16 -> 0 | N71: =GASTOS!U16 -> 0 | O71: =GASTOS!W16 -> 0 | P71: =GASTOS!Y16 -> 0 | Q71: =GASTOS!AA16 -> 0 | S71: =SUM(F71:Q71) -> 0
D72: REALIZADO | F72: =GASTOS!F16 -> 0 | G72: =GASTOS!H16 -> 0 | H72: =GASTOS!J16 -> 0 | I72: =GASTOS!L16 -> 0 | J72: =GASTOS!N16 -> 0 | K72: =GASTOS!P16 -> 0 | L72: =GASTOS!R16 -> 0 | M72: =GASTOS!T16 -> 0 | N72: =GASTOS!V16 -> 0 | O72: =GASTOS!X16 -> 0 | P72: =GASTOS!Z16 -> 0 | Q72: =GASTOS!AB16 -> 0 | S72: =SUM(F72:Q72) -> 0
G89: JAN | H89: FEV | I89: MAR | J89: ABR | K89: MAI | L89: JUN | M89: JUL | N89: AGO | O89: SET | P89: OUT | Q89: NOV | R89: DEZ
F90: =GASTOS!C18 -> DESPESAS OPERACIONAIS | G90: =GASTOS!F22 -> 0 | H90: =GASTOS!H22 -> 0 | I90: =GASTOS!J22 -> 0 | J90: =GASTOS!L22 -> 0 | K90: =GASTOS!N22 -> 0 | L90: =GASTOS!P22 -> 0 | M90: =GASTOS!R22 -> 0 | N90: =GASTOS!T22 -> 0 | O90: =GASTOS!V22 -> 0 | P90: =GASTOS!X22 -> 0 | Q90: =GASTOS!Z22 -> 0 | R90: =GASTOS!AB22 -> 0
F91: =GASTOS!C84 -> CUSTOS PRODUTOS/SERVIÇOS | G91: =GASTOS!F88 -> 0 | H91: =GASTOS!H88 -> 0 | I91: =GASTOS!J88 -> 0 | J91: =GASTOS!L88 -> 0 | K91: =GASTOS!N88 -> 0 | L91: =GASTOS!P88 -> 0 | M91: =GASTOS!R88 -> 0 | N91: =GASTOS!T88 -> 0 | O91: =GASTOS!V88 -> 0 | P91: =GASTOS!X88 -> 0 | Q91: =GASTOS!Z88 -> 0 | R91: =GASTOS!AB88 -> 0
F92: =GASTOS!C110 -> IMPOSTOS E TAXAS | G92: =GASTOS!F114 -> 0 | H92: =GASTOS!H114 -> 0 | I92: =GASTOS!J114 -> 0 | J92: =GASTOS!L114 -> 0 | K92: =GASTOS!N114 -> 0 | L92: =GASTOS!P114 -> 0 | M92: =GASTOS!R114 -> 0 | N92: =GASTOS!T114 -> 0 | O92: =GASTOS!V114 -> 0 | P92: =GASTOS!X114 -> 0 | Q92: =GASTOS!Z114 -> 0 | R92: =GASTOS!AB114 -> 0
F93: =GASTOS!C141 -> INVESTIMENTOS | G93: =GASTOS!F145 -> 0 | H93: =GASTOS!H145 -> 0 | I93: =GASTOS!J145 -> 0 | J93: =GASTOS!L145 -> 0 | K93: =GASTOS!N145 -> 0 | L93: =GASTOS!P145 -> 0 | M93: =GASTOS!R145 -> 0 | N93: =GASTOS!T145 -> 0 | O93: =GASTOS!V145 -> 0 | P93: =GASTOS!X145 -> 0 | Q93: =GASTOS!Z145 -> 0 | R93: =GASTOS!AB145 -> 0
F97: JAN | G97: FEV | H97: MAR | I97: ABR | J97: MAI | K97: JUN | L97: JUL | M97: AGO | N97: SET | O97: OUT | P97: NOV | Q97: DEZ | S97: TOTAL
D98: DESP. OPERACIONAIS | F98: =G90 -> 0 | G98: =H90 -> 0 | H98: =I90 -> 0 | I98: =J90 -> 0 | J98: =K90 -> 0 | K98: =L90 -> 0 | L98: =M90 -> 0 | M98: =N90 -> 0 | ... Q98: =R90 -> 0 | S98: =SUM(F98:Q98) -> 0
D99: CUSTO PROD. / SERV. | F99: =G91 -> 0 | G99: =H91 -> 0 | H99: =I91 -> 0 | I99: =J91 -> 0 | J99: =K91 -> 0 | K99: =L91 -> 0 | L99: =M91 -> 0 | M99: =N91 -> 0 | ... Q99: =R91 -> 0 | S99: =SUM(F99:Q99) -> 0
...

Sheet CADASTRO DE ITENS
E3: REGISTRO FINANCEIRO MENSAL | W3: Código
W4: R.OP.007
W5: Revisão
W6: 1.0
W7: Data
W8: 45763
W9: Página
W10: CADASTRO DE ITENS / R.OP.007
C12: CADASTRO DE ITENS
C15: NOME DO ITEM: | D15: RECEITAS | Produtos e Serviços | F15: NOME DO ITEM: | G15: RECEITAS | Outras Receitas | I15: NOME DO ITEM: | K15: RECEITAS | Receitas Financeiras | M15: NOME DO ITEM: | N15: GASTOS | Despesas Operacionais | P15: NOME DO ITEM: | Q15: GASTOS | Custos de Produtos e Serviços | S15: NOME DO ITEM: | T15: GASTOS | Impostos e Taxas | V15: NOME DO ITEM: | W15: GASTOS | Investimentos
C16: LISTAGEM | F16: LISTAGEM | I16: LISTAGEM | J16: =_xlfn.CONCAT(K16,#REF!) -> #REF! | M16: LISTAGEM | P16: LISTAGEM | S16: LISTAGEM | V16: LISTAGEM
J17: =_xlfn.CONCAT(K17,#REF!) -> #REF!
J18: =_xlfn.CONCAT(K18,#REF!) -> #REF!
J19: =_xlfn.CONCAT(K19,#REF!) -> #REF!
J20: =_xlfn.CONCAT(K20,#REF!) -> #REF!
J21: =_xlfn.CONCAT(K21,#REF!) -> #REF!
J22: =_xlfn.CONCAT(K22,#REF!) -> #REF!
J23: =_xlfn.CONCAT(K23,#REF!) -> #REF!
J24: =_xlfn.CONCAT(K24,#REF!) -> #REF!
J25: =_xlfn.CONCAT(K25,#REF!) -> #REF!
J26: =_xlfn.CONCAT(K26,#REF!) -> #REF!
J27: =_xlfn.CONCAT(K27,#REF!) -> #REF!
J28: =_xlfn.CONCAT(K28,#REF!) -> #REF!
... J31: =_xlfn.CONCAT(K31,#REF!) -> #REF!
D32: =IF([1]BaseSafra!E367="","",[1]BaseSafra!E367) | J32: =_xlfn.CONCAT(K32,#REF!) -> #REF!
D33: =IF([1]BaseSafra!E389="","",[1]BaseSafra!E389) | J33: =_xlfn.CONCAT(K33,#REF!) -> #REF!
D34: =IF([1]BaseSafra!E411="","",[1]BaseSafra!E411) | J34: =_xlfn.CONCAT(K34,#REF!) -> #REF!
D35: =IF([1]BaseSafra!E433="","",[1]BaseSafra!E433) | J35: =_xlfn.CONCAT(K35,#REF!) -> #REF!
D36: =IF([1]BaseSafra!E455="","",[1]BaseSafra!E455) | J36: =_xlfn.CONCAT(K36,#REF!) -> #REF!
D37: =IF([1]BaseSafra!E477="","",[1]BaseSafra!E477) | J37: =_xlfn.CONCAT(K37,#REF!) -> #REF!
D38: =IF([1]BaseSafra!E499="","",[1]BaseSafra!E499)
D39: =IF([1]BaseSafra!E521="","",[1]BaseSafra!E521)
D40: =IF([1]BaseSafra!E543="","",[1]BaseSafra!E543)
D41: =IF([1]BaseSafra!E565="","",[1]BaseSafra!E565)
D42: =IF([1]BaseSafra!E587="","",[1]BaseSafra!E587)
D43: =IF([1]BaseSafra!E609="","",[1]BaseSafra!E609)
D44: =IF([1]BaseSafra!E631="","",[1]BaseSafra!E631)
C146: Esta obra está licenciada com uma Licença Creative Commons Atribuição-NãoComercial 4.0 Internacional.

Sheet RECEITAS
D2: REGISTRO FINANCEIRO MENSAL | AA2: Código
AA3: R.OP.007
AA4: Revisão
AA5: 1.0
AA6: Data
AA7: 45763
AA8: Página
AA9: RECEITAS / R.OP.007
C12: RECEITAS
D14: JAN | F14: FEV | H14: MAR | J14: ABR | L14: MAI | N14: JUN | P14: JUL | R14: AGO | T14: SET | V14: OUT | X14: NOV | Z14: DEZ | AC14: SOMATÓRIO
D15: PREVISTO | E15: REALIZADO | F15: PREVISTO | G15: REALIZADO | H15: PREVISTO | I15: REALIZADO | J15: PREVISTO | K15: REALIZADO | L15: PREVISTO | M15: REALIZADO | N15: PREVISTO | O15: REALIZADO | P15: PREVISTO | Q15: REALIZADO | R15: PREVISTO | S15: REALIZADO | T15: PREVISTO | U15: REALIZADO | V15: PREVISTO | W15: REALIZADO | X15: PREVISTO | Y15: REALIZADO | Z15: PREVISTO | AA15: REALIZADO | AC15: PREVISTO | AD15: REALIZADO
C16: TOTAL MENSAL | D16: =IFERROR(SUM(D22,D55,D75),0) -> 0 | E16: =IFERROR(SUM(E22,E55,E75),0) -> 0 | F16: =IFERROR(SUM(F22,F55,F75),0) -> 0 | G16: =IFERROR(SUM(G22,G55,G75),0) -> 0 | H16: =IFERROR(SUM(H22,H55,H75),0) -> 0 | I16: =IFERROR(SUM(I22,I55,I75),0) -> 0 | J16: =IFERROR(SUM(J22,J55,J75),0) -> 0 | K16: =IFERROR(SUM(K22,K55,K75),0) -> 0 | ... AA16: =IFERROR(SUM(AA22,AA55,AA75),0) -> 0 | AC16: =IFERROR(SUM(D16,F16,H16,J16,L16,N16,P16,R16,T16,V16,X16,Z16),0) -> 0 | AD16: =IFERROR(SUM(E16,G16,I16,K16,M16,O16,Q16,S16,U16,W16,Y16,AA16),0) -> 0
C18: PRODUTOS/SERVIÇOS
C20: DESCRIÇÃO | D20: JAN | F20: FEV | H20: MAR | J20: ABR | L20: MAI | N20: JUN | P20: JUL | R20: AGO | T20: SET | V20: OUT | X20: NOV | Z20: DEZ | AC20: SOMATÓRIO
D21: PREVISTO | E21: REALIZADO | F21: PREVISTO | G21: REALIZADO | H21: PREVISTO | I21: REALIZADO | J21: PREVISTO | K21: REALIZADO | L21: PREVISTO | M21: REALIZADO | N21: PREVISTO | O21: REALIZADO | P21: PREVISTO | Q21: REALIZADO | R21: PREVISTO | S21: REALIZADO | T21: PREVISTO | U21: REALIZADO | V21: PREVISTO | W21: REALIZADO | X21: PREVISTO | Y21: REALIZADO | Z21: PREVISTO | AA21: REALIZADO | AC21: PREVISTO | AD21: REALIZADO
D22: =IFERROR(SUM(D23:D49),0) -> 0 | E22: =IFERROR(SUM(E23:E49),0) -> 0 | F22: =IFERROR(SUM(F23:F49),0) -> 0 | G22: =IFERROR(SUM(G23:G49),0) -> 0 | H22: =IFERROR(SUM(H23:H49),0) -> 0 | I22: =IFERROR(SUM(I23:I49),0) -> 0 | J22: =IFERROR(SUM(J23:J49),0) -> 0 | K22: =IFERROR(SUM(K23:K49),0) -> 0 | ... AA22: =IFERROR(SUM(AA23:AA49),0) -> 0 | AC22: =IFERROR(SUM(AC23:AC49),0) -> 0 | AD22: =IFERROR(SUM(AD23:AD49),0) -> 0
AC23: =IFERROR(SUM(D23,F23,H23,J23,L23,N23,P23,R23,T23,V23,X23,Z23),0) -> 0 | AD23: =IFERROR(SUM(E23,G23,I23,K23,M23,O23,Q23,S23,U23,W23,Y23,AA23),0) -> 0
AC24: =IFERROR(SUM(D24,F24,H24,J24,L24,N24,P24,R24,T24,V24,X24,Z24),0) -> 0 | AD24: =IFERROR(SUM(E24,G24,I24,K24,M24,O24,Q24,S24,U24,W24,Y24,AA24),0) -> 0
AC25: =IFERROR(SUM(D25,F25,H25,J25,L25,N25,P25,R25,T25,V25,X25,Z25),0) -> 0 | AD25: =IFERROR(SUM(E25,G25,I25,K25,M25,O25,Q25,S25,U25,W25,Y25,AA25),0) -> 0
AC26: =IFERROR(SUM(D26,F26,H26,J26,L26,N26,P26,R26,T26,V26,X26,Z26),0) -> 0 | AD26: =IFERROR(SUM(E26,G26,I26,K26,M26,O26,Q26,S26,U26,W26,Y26,AA26),0) -> 0
AC27: =IFERROR(SUM(D27,F27,H27,J27,L27,N27,P27,R27,T27,V27,X27,Z27),0) -> 0 | AD27: =IFERROR(SUM(E27,G27,I27,K27,M27,O27,Q27,S27,U27,W27,Y27,AA27),0) -> 0
AC28: =IFERROR(SUM(D28,F28,H28,J28,L28,N28,P28,R28,T28,V28,X28,Z28),0) -> 0 | AD28: =IFERROR(SUM(E28,G28,I28,K28,M28,O28,Q28,S28,U28,W28,Y28,AA28),0) -> 0
AC29: =IFERROR(SUM(D29,F29,H29,J29,L29,N29,P29,R29,T29,V29,X29,Z29),0) -> 0 | AD29: =IFERROR(SUM(E29,G29,I29,K29,M29,O29,Q29,S29,U29,W29,Y29,AA29),0) -> 0
AC30: =IFERROR(SUM(D30,F30,H30,J30,L30,N30,P30,R30,T30,V30,X30,Z30),0) -> 0 | AD30: =IFERROR(SUM(E30,G30,I30,K30,M30,O30,Q30,S30,U30,W30,Y30,AA30),0) -> 0
AC31: =IFERROR(SUM(D31,F31,H31,J31,L31,N31,P31,R31,T31,V31,X31,Z31),0) -> 0 | AD31: =IFERROR(SUM(E31,G31,I31,K31,M31,O31,Q31,S31,U31,W31,Y31,AA31),0) -> 0
AC32: =IFERROR(SUM(D32,F32,H32,J32,L32,N32,P32,R32,T32,V32,X32,Z32),0) -> 0 | AD32: =IFERROR(SUM(E32,G32,I32,K32,M32,O32,Q32,S32,U32,W32,Y32,AA32),0) -> 0
AC33: =IFERROR(SUM(D33,F33,H33,J33,L33,N33,P33,R33,T33,V33,X33,Z33),0) -> 0 | AD33: =IFERROR(SUM(E33,G33,I33,K33,M33,O33,Q33,S33,U33,W33,Y33,AA33),0) -> 0
AC34: =IFERROR(SUM(D34,F34,H34,J34,L34,N34,P34,R34,T34,V34,X34,Z34),0) -> 0 | AD34: =IFERROR(SUM(E34,G34,I34,K34,M34,O34,Q34,S34,U34,W34,Y34,AA34),0) -> 0
... AC49: =IFERROR(SUM(D49,F49,H49,J49,L49,N49,P49,R49,T49,V49,X49,Z49),0) -> 0 | AD49: =IFERROR(SUM(E49,G49,I49,K49,M49,O49,Q49,S49,U49,W49,Y49,AA49),0) -> 0
C51: OUTRAS RECEITAS
C53: DESCRIÇÃO | D53: JAN | F53: FEV | H53: MAR | J53: ABR | L53: MAI | N53: JUN | P53: JUL | R53: AGO | T53: SET | V53: OUT | X53: NOV | Z53: DEZ | AC53: SOMATÓRIO
D54: PREVISTO | E54: REALIZADO | F54: PREVISTO | G54: REALIZADO | H54: PREVISTO | I54: REALIZADO | J54: PREVISTO | K54: REALIZADO | L54: PREVISTO | M54: REALIZADO | N54: PREVISTO | O54: REALIZADO | P54: PREVISTO | Q54: REALIZADO | R54: PREVISTO | S54: REALIZADO | T54: PREVISTO | U54: REALIZADO | V54: PREVISTO | W54: REALIZADO | X54: PREVISTO | Y54: REALIZADO | Z54: PREVISTO | AA54: REALIZADO | AC54: PREVISTO | AD54: REALIZADO
D55: =IFERROR(SUM(D56:D69),0) -> 0 | E55: =IFERROR(SUM(E56:E69),0) -> 0 | F55: =IFERROR(SUM(F56:F69),0) -> 0 | G55: =IFERROR(SUM(G56:G69),0) -> 0 | H55: =IFERROR(SUM(H56:H69),0) -> 0 | I55: =IFERROR(SUM(I56:I69),0) -> 0 | J55: =IFERROR(SUM(J56:J69),0) -> 0 | K55: =IFERROR(SUM(K56:K69),0) -> 0 | ... AA55: =IFERROR(SUM(AA56:AA69),0) -> 0 | AC55: =IFERROR(SUM(AC56:AC69),0) -> 0 | AD55: =IFERROR(SUM(AD56:AD69),0) -> 0
AC56: =IFERROR(SUM(D56,F56,H56,J56,L56,N56,P56,R56,T56,V56,X56,Z56),0) -> 0 | AD56: =IFERROR(SUM(E56,G56,I56,K56,M56,O56,Q56,S56,U56,W56,Y56,AA56),0) -> 0
AC57: =IFERROR(SUM(D57,F57,H57,J57,L57,N57,P57,R57,T57,V57,X57,Z57),0) -> 0 | AD57: =IFERROR(SUM(E57,G57,I57,K57,M57,O57,Q57,S57,U57,W57,Y57,AA57),0) -> 0
AC58: =IFERROR(SUM(D58,F58,H58,J58,L58,N58,P58,R58,T58,V58,X58,Z58),0) -> 0 | AD58: =IFERROR(SUM(E58,G58,I58,K58,M58,O58,Q58,S58,U58,W58,Y58,AA58),0) -> 0
AC59: =IFERROR(SUM(D59,F59,H59,J59,L59,N59,P59,R59,T59,V59,X59,Z59),0) -> 0 | AD59: =IFERROR(SUM(E59,G59,I59,K59,M59,O59,Q59,S59,U59,W59,Y59,AA59),0) -> 0
AC60: =IFERROR(SUM(D60,F60,H60,J60,L60,N60,P60,R60,T60,V60,X60,Z60),0) -> 0 | AD60: =IFERROR(SUM(E60,G60,I60,K60,M60,O60,Q60,S60,U60,W60,Y60,AA60),0) -> 0
AC61: =IFERROR(SUM(D61,F61,H61,J61,L61,N61,P61,R61,T61,V61,X61,Z61),0) -> 0 | AD61: =IFERROR(SUM(E61,G61,I61,K61,M61,O61,Q61,S61,U61,W61,Y61,AA61),0) -> 0
AC62: =IFERROR(SUM(D62,F62,H62,J62,L62,N62,P62,R62,T62,V62,X62,Z62),0) -> 0 | AD62: =IFERROR(SUM(E62,G62,I62,K62,M62,O62,Q62,S62,U62,W62,Y62,AA62),0) -> 0
...

Sheet GASTOS
D2: REGISTRO FINANCEIRO MENSAL | AB2: Código
AB3: R.OP.007
AB4: Revisão
AB5: 1.0
AB6: Data
AB7: 45763
AB8: Página
AB9: RECEITAS / R.OP.007
C12: GASTOS
E14: JAN | G14: FEV | I14: MAR | K14: ABR | M14: MAI | O14: JUN | Q14: JUL | S14: AGO | U14: SET | W14: OUT | Y14: NOV | AA14: DEZ | AD14: SOMATÓRIO
E15: PREVISTO | F15: REALIZADO | G15: PREVISTO | H15: REALIZADO | I15: PREVISTO | J15: REALIZADO | K15: PREVISTO | L15: REALIZADO | M15: PREVISTO | N15: REALIZADO | O15: PREVISTO | P15: REALIZADO | Q15: PREVISTO | R15: REALIZADO | S15: PREVISTO | T15: REALIZADO | U15: PREVISTO | V15: REALIZADO | W15: PREVISTO | X15: REALIZADO | Y15: PREVISTO | Z15: REALIZADO | AA15: PREVISTO | AB15: REALIZADO | AD15: PREVISTO | AE15: REALIZADO
C16: TOTAL MENSAL | E16: =IFERROR(SUM(E22,E88,E145,E114),0) -> 0 | F16: =IFERROR(SUM(F22,F88,F145,F114),0) -> 0 | G16: =IFERROR(SUM(G22,G88,G145,G114),0) -> 0 | H16: =IFERROR(SUM(H22,H88,H145,H114),0) -> 0 | I16: =IFERROR(SUM(I22,I88,I145,I114),0) -> 0 | J16: =IFERROR(SUM(J22,J88,J145,J114),0) -> 0 | K16: =IFERROR(SUM(K22,K88,K145,K114),0) -> 0 | L16: =IFERROR(SUM(L22,L88,L145,L114),0) -> 0 | ... AB16: =IFERROR(SUM(AB22,AB88,AB145,AB114),0) -> 0 | AD16: =IFERROR(SUM(E16,G16,I16,K16,M16,O16,Q16,S16,U16,W16,Y16,AA16),0) -> 0 | AE16: =IFERROR(SUM(F16,H16,J16,L16,N16,P16,R16,T16,V16,X16,Z16,AB16),0) -> 0
C18: DESPESAS OPERACIONAIS
C20: SUBCATEGORIA | D20: DESCRIÇÃO | E20: JAN | G20: FEV | I20: MAR | K20: ABR | M20: MAI | O20: JUN | Q20: JUL | S20: AGO | U20: SET | W20: OUT | Y20: NOV | AA20: DEZ | AD20: SOMATÓRIO
E21: PREVISTO | F21: REALIZADO | G21: PREVISTO | H21: REALIZADO | I21: PREVISTO | J21: REALIZADO | K21: PREVISTO | L21: REALIZADO | M21: PREVISTO | N21: REALIZADO | O21: PREVISTO | P21: REALIZADO | Q21: PREVISTO | R21: REALIZADO | S21: PREVISTO | T21: REALIZADO | U21: PREVISTO | V21: REALIZADO | W21: PREVISTO | X21: REALIZADO | Y21: PREVISTO | Z21: REALIZADO | AA21: PREVISTO | AB21: REALIZADO | AD21: PREVISTO | AE21: REALIZADO
E22: =IFERROR(SUM(E23:E82),0) -> 0 | F22: =IFERROR(SUM(F23:F82),0) -> 0 | G22: =IFERROR(SUM(G23:G82),0) -> 0 | H22: =IFERROR(SUM(H23:H82),0) -> 0 | I22: =IFERROR(SUM(I23:I82),0) -> 0 | J22: =IFERROR(SUM(J23:J82),0) -> 0 | K22: =IFERROR(SUM(K23:K82),0) -> 0 | L22: =IFERROR(SUM(L23:L82),0) -> 0 | ... AB22: =IFERROR(SUM(AB23:AB82),0) -> 0 | AD22: =IFERROR(SUM(AD23:AD82),0) -> 0 | AE22: =IFERROR(SUM(AE23:AE82),0) -> 0
AD23: =IFERROR(SUM(E23,G23,I23,K23,M23,O23,Q23,S23,U23,W23,Y23,AA23),0) -> 0 | AE23: =IFERROR(SUM(F23,H23,J23,L23,N23,P23,R23,T23,V23,X23,Z23,AB23),0) -> 0
AD24: =IFERROR(SUM(E24,G24,I24,K24,M24,O24,Q24,S24,U24,W24,Y24,AA24),0) -> 0 | AE24: =IFERROR(SUM(F24,H24,J24,L24,N24,P24,R24,T24,V24,X24,Z24,AB24),0) -> 0
AD25: =IFERROR(SUM(E25,G25,I25,K25,M25,O25,Q25,S25,U25,W25,Y25,AA25),0) -> 0 | AE25: =IFERROR(SUM(F25,H25,J25,L25,N25,P25,R25,T25,V25,X25,Z25,AB25),0) -> 0
AD26: =IFERROR(SUM(E26,G26,I26,K26,M26,O26,Q26,S26,U26,W26,Y26,AA26),0) -> 0 | AE26: =IFERROR(SUM(F26,H26,J26,L26,N26,P26,R26,T26,V26,X26,Z26,AB26),0) -> 0
AD27: =IFERROR(SUM(E27,G27,I27,K27,M27,O27,Q27,S27,U27,W27,Y27,AA27),0) -> 0 | AE27: =IFERROR(SUM(F27,H27,J27,L27,N27,P27,R27,T27,V27,X27,Z27,AB27),0) -> 0
AD28: =IFERROR(SUM(E28,G28,I28,K28,M28,O28,Q28,S28,U28,W28,Y28,AA28),0) -> 0 | AE28: =IFERROR(SUM(F28,H28,J28,L28,N28,P28,R28,T28,V28,X28,Z28,AB28),0) -> 0
AD29: =IFERROR(SUM(E29,G29,I29,K29,M29,O29,Q29,S29,U29,W29,Y29,AA29),0) -> 0 | AE29: =IFERROR(SUM(F29,H29,J29,L29,N29,P29,R29,T29,V29,X29,Z29,AB29),0) -> 0
AD30: =IFERROR(SUM(E30,G30,I30,K30,M30,O30,Q30,S30,U30,W30,Y30,AA30),0) -> 0 | AE30: =IFERROR(SUM(F30,H30,J30,L30,N30,P30,R30,T30,V30,X30,Z30,AB30),0) -> 0
AD31: =IFERROR(SUM(E31,G31,I31,K31,M31,O31,Q31,S31,U31,W31,Y31,AA31),0) -> 0 | AE31: =IFERROR(SUM(F31,H31,J31,L31,N31,P31,R31,T31,V31,X31,Z31,AB31),0) -> 0
AD32: =IFERROR(SUM(E32,G32,I32,K32,M32,O32,Q32,S32,U32,W32,Y32,AA32),0) -> 0 | AE32: =IFERROR(SUM(F32,H32,J32,L32,N32,P32,R32,T32,V32,X32,Z32,AB32),0) -> 0
AD33: =IFERROR(SUM(E33,G33,I33,K33,M33,O33,Q33,S33,U33,W33,Y33,AA33),0) -> 0 | AE33: =IFERROR(SUM(F33,H33,J33,L33,N33,P33,R33,T33,V33,X33,Z33,AB33),0) -> 0
AD34: =IFERROR(SUM(E34,G34,I34,K34,M34,O34,Q34,S34,U34,W34,Y34,AA34),0) -> 0 | AE34: =IFERROR(SUM(F34,H34,J34,L34,N34,P34,R34,T34,V34,X34,Z34,AB34),0) -> 0
... AD82: =IFERROR(SUM(E82,G82,I82,K82,M82,O82,Q82,S82,U82,W82,Y82,AA82),0) -> 0 | AE82: =IFERROR(SUM(F82,H82,J82,L82,N82,P82,R82,T82,V82,X82,Z82,AB82),0) -> 0
C84: CUSTOS PRODUTOS/SERVIÇOS
C86: SUBCATEGORIA | D86: DESCRIÇÃO | E86: JAN | G86: FEV | I86: MAR | K86: ABR | M86: MAI | O86: JUN | Q86: JUL | S86: AGO | U86: SET | W86: OUT | Y86: NOV | AA86: DEZ | AD86: SOMATÓRIO
E87: PREVISTO | F87: REALIZADO | G87: PREVISTO | H87: REALIZADO | I87: PREVISTO | J87: REALIZADO | K87: PREVISTO | L87: REALIZADO | M87: PREVISTO | N87: REALIZADO | O87: PREVISTO | P87: REALIZADO | Q87: PREVISTO | R87: REALIZADO | S87: PREVISTO | T87: REALIZADO | U87: PREVISTO | V87: REALIZADO | W87: PREVISTO | X87: REALIZADO | Y87: PREVISTO | Z87: REALIZADO | AA87: PREVISTO | AB87: REALIZADO | AD87: PREVISTO | AE87: REALIZADO
E88: =IFERROR(SUM(E89:E108),0) -> 0 | F88: =IFERROR(SUM(F89:F108),0) -> 0 | G88: =IFERROR(SUM(G89:G108),0) -> 0 | H88: =IFERROR(SUM(H89:H108),0) -> 0 | I88: =IFERROR(SUM(I89:I108),0) -> 0 | J88: =IFERROR(SUM(J89:J108),0) -> 0 | K88: =IFERROR(SUM(K89:K108),0) -> 0 | L88: =IFERROR(SUM(L89:L108),0) -> 0 | ... AB88: =IFERROR(SUM(AB89:AB108),0) -> 0 | AD88: =IFERROR(SUM(AD89:AD108),0) -> 0 | AE88: =IFERROR(SUM(AE89:AE108),0) -> 0
AD89: =IFERROR(SUM(E89,G89,I89,K89,M89,O89,Q89,S89,U89,W89,Y89,AA89),0) -> 0 | AE89: =IFERROR(SUM(F89,H89,J89,L89,N89,P89,R89,T89,V89,X89,Z89,AB89),0) -> 0
AD90: =IFERROR(SUM(E90,G90,I90,K90,M90,O90,Q90,S90,U90,W90,Y90,AA90),0) -> 0 | AE90: =IFERROR(SUM(F90,H90,J90,L90,N90,P90,R90,T90,V90,X90,Z90,AB90),0) -> 0
AD91: =IFERROR(SUM(E91,G91,I91,K91,M91,O91,Q91,S91,U91,W91,Y91,AA91),0) -> 0 | AE91: =IFERROR(SUM(F91,H91,J91,L91,N91,P91,R91,T91,V91,X91,Z91,AB91),0) -> 0
AD92: =IFERROR(SUM(E92,G92,I92,K92,M92,O92,Q92,S92,U92,W92,Y92,AA92),0) -> 0 | AE92: =IFERROR(SUM(F92,H92,J92,L92,N92,P92,R92,T92,V92,X92,Z92,AB92),0) -> 0
AD93: =IFERROR(SUM(E93,G93,I93,K93,M93,O93,Q93,S93,U93,W93,Y93,AA93),0) -> 0 | AE93: =IFERROR(SUM(F93,H93,J93,L93,N93,P93,R93,T93,V93,X93,Z93,AB93),0) -> 0
AD94: =IFERROR(SUM(E94,G94,I94,K94,M94,O94,Q94,S94,U94,W94,Y94,AA94),0) -> 0 | AE94: =IFERROR(SUM(F94,H94,J94,L94,N94,P94,R94,T94,V94,X94,Z94,AB94),0) -> 0
AD95: =IFERROR(SUM(E95,G95,I95,K95,M95,O95,Q95,S95,U95,W95,Y95,AA95),0) -> 0 | AE95: =IFERROR(SUM(F95,H95,J95,L95,N95,P95,R95,T95,V95,X95,Z95,AB95),0) -> 0
...

Sheet PLANO DE CONTAS
E2: PLANO DE CONTAS | I2: Código
I3: R.PD.023
I4: Revisão
I5: 2.0
I6: Data
I7: 45513
I8: Página
I9: PLANO DE CONTAS / R.PD.023
B11: PLANO DE CONTAS
C14: RECEITAS
C16: PRODUTOS / SERVIÇOS
C45: OUTRAS RECEITAS
C47: Empréstimos de instituições
C48: Empréstimos de Sócios
C49: Integralização de capital
C50: Reembolso
C51: Outros
C61: RECEITAS FINANCEIRAS
C63: Crédito de Cartão
C64: Juros
C65: Outros
... C75: Esta obra está licenciada com uma Licença Creative Commons Atribuição-NãoComercial 4.0 Internacional.
E79: PLANO DE CONTAS | I79: Código
I81: Revisão
I82: 1.0
I83: Data
I85: Página
B88: PLANO DE CONTAS
C91: DESPESAS
C93: DESPESAS OPERACIONAIS | G93: CUSTO DE PRODUTOS/SERVIÇOS
C95: 13º Salário | G95: Fretes
C96: Adiantamento Salarial | G96: Matéria-prima
C97: Agua | G97: Prestação de Serviços
C98: Aluguel de Equipamentos
C99: Aluguel de Imóveis
C100: Anuidades/Mensalidades
C101: Associação Comercial
C102: Bonificações
C103: Brindes e Doações
C104: Cartório
...

Sheet CONCILIAÇÃO
C2: CONCILIAÇÃO | M2: Código
M3: R.PD.023
M4: Revisão
M5: 2.0
M6: Data
M7: 45513
M8: Página
M9: CONCILIAÇÃO / R.PD.023
B11: AVALIAÇÃO FINANCEIRA
B13: CONTA 01 | C13: jan/23 | D13: fev/23 | E13: mar/23 | F13: abr/23 | G13: mai/23 | H13: jun/23 | I13: jul/23 | J13: ago/23 | K13: set/23 | L13: out/23 | M13: nov/23 | N13: dez/23
B14: SALDO INICIAL:
B15: SALDO FINAL:
B17: CONTA 02 | C17: jan/23 | D17: fev/23 | E17: mar/23 | F17: abr/23 | G17: mai/23 | H17: jun/23 | I17: jul/23 | J17: ago/23 | K17: set/23 | L17: out/23 | M17: nov/23 | N17: dez/23
B18: SALDO INICIAL:
B19: SALDO FINAL:
B21: CAIXA FÍSICO | C21: jan/23 | D21: fev/23 | E21: mar/23 | F21: abr/23 | G21: mai/23 | H21: jun/23 | I21: jul/23 | J21: ago/23 | K21: set/23 | L21: out/23 | M21: nov/23 | N21: dez/23
B22: SALDO INICIAL:
B23: SALDO FINAL:
B25: CONFERÊNCIA | C25: jan/23 | D25: fev/23 | E25: mar/23 | F25: abr/23 | G25: mai/23 | H25: jun/23 | I25: jul/23 | J25: ago/23 | K25: set/23 | L25: out/23 | M25: nov/23 | N25: dez/23
B26: SALDO INICIAL CONTAS | C26: =C14+C18+C22 -> 0 | D26: =D14+D18+D22 -> 0 | E26: =E14+E18+E22 -> 0 | F26: =F14+F18+F22 -> 0 | G26: =G14+G18+G22 -> 0 | H26: =H14+H18+H22 -> 0 | I26: =I14+I18+I22 -> 0 | J26: =J14+J18+J22 -> 0 | ... N26: =N14+N18+N22 -> 0
B27: SALDO FINAL CONTAS | C27: =C15+C19+C23 -> 0 | D27: =D15+D19+D23 -> 0 | E27: =E15+E19+E23 -> 0 | F27: =F15+F19+F23 -> 0 | G27: =G15+G19+G23 -> 0 | H27: =H15+H19+H23 -> 0 | I27: =I15+I19+I23 -> 0 | J27: =J15+J19+J23 -> 0 | ... N27: =N15+N19+N23 -> 0
B28: (+) RECEITAS | C28: =RECEITAS!E16 -> 0 | D28: =RECEITAS!G16 -> 0 | E28: =RECEITAS!I16 -> 0 | F28: =RECEITAS!K16 -> 0 | G28: =RECEITAS!M16 -> 0 | H28: =RECEITAS!O16 -> 0 | I28: =RECEITAS!Q16 -> 0 | J28: =RECEITAS!S16 -> 0 | K28: =RECEITAS!U16 -> 0 | L28: =RECEITAS!W16 -> 0 | M28: =RECEITAS!Y16 -> 0 | N28: =RECEITAS!AA16 -> 0
B29: (-) GASTOS | C29: =GASTOS!F16 -> 0 | D29: =GASTOS!H16 -> 0 | E29: =GASTOS!J16 -> 0 | F29: =GASTOS!L16 -> 0 | G29: =GASTOS!N16 -> 0 | H29: =GASTOS!P16 -> 0 | I29: =GASTOS!R16 -> 0 | J29: =GASTOS!T16 -> 0 | K29: =GASTOS!V16 -> 0 | L29: =GASTOS!X16 -> 0 | M29: =GASTOS!Z16 -> 0 | N29: =GASTOS!AB16 -> 0
B30: GERAÇÃO DE CAIXA EXTRATOS | C30: =C27-C26 -> 0 | D30: =D27-D26 -> 0 | E30: =E27-E26 -> 0 | F30: =F27-F26 -> 0 | G30: =G27-G26 -> 0 | H30: =H27-H26 -> 0 | I30: =I27-I26 -> 0 | J30: =J27-J26 -> 0 | ... N30: =N27-N26 -> 0
B31: GERAÇÃO DE CAIXA PLANILHA | C31: =C28-C29 -> 0 | D31: =D28-D29 -> 0 | E31: =E28-E29 -> 0 | F31: =F28-F29 -> 0 | G31: =G28-G29 -> 0 | H31: =H28-H29 -> 0 | I31: =I28-I29 -> 0 | J31: =J28-J29 -> 0 | ... N31: =N28-N29 -> 0
B32: DIFERENÇA | C32: =C30-C31 -> 0 | D32: =D30-D31 -> 0 | E32: =E30-E31 -> 0 | F32: =F30-F31 -> 0 | G32: =G30-G31 -> 0 | H32: =H30-H31 -> 0 | I32: =I30-I31 -> 0 | J32: =J30-J31 -> 0 | ... N32: =N30-N31 -> 0
C35: This work is licensed under a Creative Commons Attribution-NonCommercial 4.0 International License.
